<?xml version="1.0" ?>
<!-- =================================================================================== -->
<!-- |    This document was autogenerated by xacro from scorbot.urdf.xacro             | -->
<!-- |    EDITING THIS FILE BY HAND IS NOT RECOMMENDED                                 | -->
<!-- =================================================================================== -->
<robot name="scorbot" xmlns:xacro="http://ros.org/wiki/xacro">
  <!-- URDF Materials -->
  <material name="Grey1">
    <color rgba="0.1 0.1 0.1 1"/>
  </material>
  <material name="Grey2">
    <color rgba="0.2 0.2 0.2 1"/>
  </material>
  <material name="Grey3">
    <color rgba="0.3 0.3 0.3 1"/>
  </material>
  <material name="Body">
    <color rgba="0.85 0.85 0.85 1"/>
  </material>
  <material name="Head">
    <color rgba="0.75 0.75 0.75 1"/>
  </material>
  <!-- Gazebo macros -->
  <!-- ROS Control -->
  <!-- For Effort controllers -->
  <!-- For Position controllers -->
  <!-- No gravity links -->
  <!-- Normal links -->
  <!-- Normal links DAE file -->
  <!-- Wheel links -->
  <!-- Gripper links -->
  <!-- Depth camera plugin -->
  <!-- Base wheels plugin -->
  <!-- Laser sensor plugin -->
  <!-- Gazebo elements -->
  <!-- Gazebo Links material -->
  <gazebo reference="base">
    <mu1>0.2</mu1>
    <mu2>0.2</mu2>
  </gazebo>
  <gazebo reference="body">
    <mu1>0.2</mu1>
    <mu2>0.2</mu2>
  </gazebo>
  <gazebo reference="upper_arm">
    <mu1>0.2</mu1>
    <mu2>0.2</mu2>
  </gazebo>
  <gazebo reference="forearm">
    <mu1>0.2</mu1>
    <mu2>0.2</mu2>
  </gazebo>
  <gazebo reference="flange">
    <mu1>0.2</mu1>
    <mu2>0.2</mu2>
  </gazebo>
  <gazebo reference="right_finger">
    <mu1>0.2</mu1>
    <mu2>0.2</mu2>
  </gazebo>
  <gazebo reference="left_finger">
    <mu1>0.2</mu1>
    <mu2>0.2</mu2>
  </gazebo>
  <!-- Transmissions -->
  <gazebo>
    <plugin filename="libgazebo_ros_control.so" name="ros_control">
      <robotNamespace>scorbot/</robotNamespace>
    </plugin>
  </gazebo>
  <transmission name="base_transmission">
    <type>transmission_interface/SimpleTransmission</type>
    <joint name="base">
      <hardwareInterface>PositionJointInterface</hardwareInterface>
    </joint>
    <actuator name="base_motor">
      <hardwareInterface>PositionJointInterface</hardwareInterface>
      <mechanicalReduction>1</mechanicalReduction>
    </actuator>
  </transmission>
  <transmission name="shoulder_transmission">
    <type>transmission_interface/SimpleTransmission</type>
    <joint name="shoulder">
      <hardwareInterface>PositionJointInterface</hardwareInterface>
    </joint>
    <actuator name="shoulder_motor">
      <hardwareInterface>PositionJointInterface</hardwareInterface>
      <mechanicalReduction>1</mechanicalReduction>
    </actuator>
  </transmission>
  <transmission name="elbow_transmission">
    <type>transmission_interface/SimpleTransmission</type>
    <joint name="elbow">
      <hardwareInterface>PositionJointInterface</hardwareInterface>
    </joint>
    <actuator name="elbow_motor">
      <hardwareInterface>PositionJointInterface</hardwareInterface>
      <mechanicalReduction>1</mechanicalReduction>
    </actuator>
  </transmission>
  <transmission name="pitch_transmission">
    <type>transmission_interface/SimpleTransmission</type>
    <joint name="pitch">
      <hardwareInterface>PositionJointInterface</hardwareInterface>
    </joint>
    <actuator name="pitch_motor">
      <hardwareInterface>PositionJointInterface</hardwareInterface>
      <mechanicalReduction>1</mechanicalReduction>
    </actuator>
  </transmission>
  <transmission name="roll_transmission">
    <type>transmission_interface/SimpleTransmission</type>
    <joint name="roll">
      <hardwareInterface>PositionJointInterface</hardwareInterface>
    </joint>
    <actuator name="roll_motor">
      <hardwareInterface>PositionJointInterface</hardwareInterface>
      <mechanicalReduction>1</mechanicalReduction>
    </actuator>
  </transmission>
  <transmission name="gripper_finger_left_joint_transmission">
    <type>transmission_interface/SimpleTransmission</type>
    <joint name="gripper_finger_left_joint">
      <hardwareInterface>EffortJointInterface</hardwareInterface>
    </joint>
    <actuator name="gripper_finger_left_joint_motor">
      <hardwareInterface>EffortJointInterface</hardwareInterface>
      <mechanicalReduction>1</mechanicalReduction>
    </actuator>
  </transmission>
  <transmission name="gripper_finger_right_joint_transmission">
    <type>transmission_interface/SimpleTransmission</type>
    <joint name="gripper_finger_right_joint">
      <hardwareInterface>EffortJointInterface</hardwareInterface>
    </joint>
    <actuator name="gripper_finger_right_joint_motor">
      <hardwareInterface>EffortJointInterface</hardwareInterface>
      <mechanicalReduction>1</mechanicalReduction>
    </actuator>
  </transmission>
  <!-- Constants -->
  <!-- Joint limits in radians -->
  <!-- Gripper joint limits -->
  <!-- Attach to the world frame -->
  <link name="world"/>
  <joint name="fixed" type="fixed">
    <parent link="world"/>
    <child link="base"/>
  </joint>
  <link name="base">
    <inertial>
      <origin rpy="0 0 0" xyz="-5.6661E-09 -4.8129E-10 0.049865"/>
      <mass value="3.5594"/>
      <inertia ixx="0.025688" ixy="-2.4368E-10" ixz="1.2537E-10" iyy="0.025688" iyz="-3.2961E-12" izz="0.028476"/>
    </inertial>
    <visual>
      <origin rpy="1.5707963268 0 0" xyz="0 0 0"/>
      <geometry>
        <mesh filename="package://scorbot_description/meshes/base.dae"/>
      </geometry>
      <material name="">
        <color rgba="0.5 0.5 0.5 1"/>
      </material>
    </visual>
    <collision>
      <origin rpy="0 0 0" xyz="0 0 0.0225"/>
      <geometry>
        <cylinder length="0.045" radius="0.16"/>
      </geometry>
    </collision>
    <collision>
      <origin rpy="0 0 0" xyz="0 0 0.085"/>
      <geometry>
        <cylinder length="0.170" radius="0.05"/>
      </geometry>
    </collision>
  </link>
  <link name="body">
    <inertial>
      <origin rpy="0 0 0" xyz="-0.072272 -0.0016694 0.145"/>
      <mass value="9.7868"/>
      <inertia ixx="0.05511" ixy="-0.001985" ixz="0.0061208" iyy="0.12037" iyz="-0.00070806" izz="0.10965"/>
    </inertial>
    <visual>
      <origin rpy="-1.5707963268 0 0" xyz="0 0 0"/>
      <geometry>
        <mesh filename="package://scorbot_description/meshes/body.dae"/>
      </geometry>
      <material name="">
        <color rgba="0.5 0.5 0.5 1"/>
      </material>
    </visual>
    <collision>
      <origin rpy="0 0 0" xyz="-0.08 0 0.125"/>
      <geometry>
        <box size="0.380 0.18 0.25"/>
      </geometry>
    </collision>
  </link>
  <joint name="base" type="revolute">
    <origin rpy="0 0 0" xyz="0 0 0.17"/>
    <parent link="base"/>
    <child link="body"/>
    <axis xyz="0 0 1"/>
    <limit effort="30" lower="-2.18166156499" upper="2.18166156499" velocity="1.0"/>
  </joint>
  <link name="upper_arm">
    <inertial>
      <origin rpy="0 0 0" xyz="0.040893 -0.046847 -6.337E-05"/>
      <mass value="5.4535"/>
      <inertia ixx="0.010363" ixy="-0.0023486" ixz="3.9183E-05" iyy="0.1835" iyz="-4.8475E-07" izz="0.18016"/>
    </inertial>
    <visual>
      <origin rpy="-1.5707963268 0 0" xyz="0 0 0"/>
      <geometry>
        <mesh filename="package://scorbot_description/meshes/upper_arm.dae"/>
      </geometry>
      <material name="">
        <color rgba="0.5 0.5 0.5 1"/>
      </material>
    </visual>
    <collision>
      <origin rpy="0 0 0" xyz="0.06 -0.06 0"/>
      <geometry>
        <box size="0.60 0.12 0.16"/>
      </geometry>
    </collision>
  </link>
  <joint name="shoulder" type="revolute">
    <origin rpy="0 0 0" xyz="0.05 -0.096 0.1885"/>
    <parent link="body"/>
    <child link="upper_arm"/>
    <axis xyz="0 1 0"/>
    <limit effort="30" lower="-1.48352986419" upper="1.48352986419" velocity="1.0"/>
  </joint>
  <link name="forearm">
    <inertial>
      <origin rpy="0 0 0" xyz="0.073997 0.038242 4.5577E-11"/>
      <mass value="2.194"/>
      <inertia ixx="0.0025816" ixy="5.645E-05" ixz="1.195E-11" iyy="0.024687" iyz="4.1344E-12" izz="0.02443"/>
    </inertial>
    <visual>
      <origin rpy="1.5707963268 0 0" xyz="0 0 0"/>
      <geometry>
        <mesh filename="package://scorbot_description/meshes/forearm.dae"/>
      </geometry>
      <material name="">
        <color rgba="0.5 0.5 0.5 1"/>
      </material>
    </visual>
    <collision>
      <origin rpy="0 0 0" xyz="0.05 0.035 0"/>
      <geometry>
        <box size="0.3 0.095 0.12"/>
      </geometry>
    </collision>
  </link>
  <joint name="elbow" type="revolute">
    <origin rpy="0 0 0" xyz="0.3 0.021 0"/>
    <parent link="upper_arm"/>
    <child link="forearm"/>
    <axis xyz="0 -1 0"/>
    <limit effort="30" lower="-1.96349540849" upper="1.96349540849" velocity="1.0"/>
  </joint>
  <link name="flange">
    <inertial>
      <origin rpy="0 0 0" xyz="0.0069957 -0.02 5.5511E-17"/>
      <mass value="0.24441"/>
      <inertia ixx="0.00014819" ixy="1.6491E-20" ixz="-1.653E-19" iyy="0.00028003" iyz="5.3591E-21" izz="0.00021086"/>
    </inertial>
    <visual>
      <origin rpy="-1.5707963268 0 0" xyz="0 0 0"/>
      <geometry>
        <mesh filename="package://scorbot_description/meshes/flange.dae"/>
      </geometry>
      <material name="">
        <color rgba="0.1 0.1 0.1 1"/>
      </material>
    </visual>
    <collision>
      <origin rpy="-1.5707963268 0 0" xyz="0 -0.024 0"/>
      <geometry>
        <cylinder length="0.105" radius="0.05"/>
      </geometry>
    </collision>
  </link>
  <joint name="pitch" type="revolute">
    <origin rpy="0 0 0" xyz="0.25 0.058 0"/>
    <parent link="forearm"/>
    <child link="flange"/>
    <axis xyz="0 -1 0"/>
    <limit effort="30" lower="-1.57079632679" upper="1.57079632679" velocity="1.0"/>
  </joint>
  <joint name="roll" type="revolute">
    <origin rpy="0 0 0" xyz="0.054 -0.024 0"/>
    <parent link="flange"/>
    <child link="gripper_base_link"/>
    <axis xyz="1 0 0"/>
    <limit effort="30" lower="-3.14159265358" upper="3.14159265358" velocity="1.0"/>
  </joint>
  <!-- Gripper -->
  <link name="gripper_base_link">
    <inertial>
      <origin rpy="0 0 0" xyz="0.0593648790750631 0 0"/>
      <mass value="1.59125921054032"/>
      <inertia ixx="0.00147991252859225" ixy="1.34230402513126E-19" ixz="1.07467005492524E-19" iyy="0.00232303179944379" iyz="-4.07594317291221E-20" izz="0.00291367454744379"/>
    </inertial>
    <visual>
      <origin rpy="-1.5707963268 0 0" xyz="0 0 0"/>
      <geometry>
        <mesh filename="package://scorbot_description/meshes/gripper_base.dae"/>
      </geometry>
      <material name="">
        <color rgba="0.1 0.1 0.1 1"/>
      </material>
    </visual>
    <collision>
      <origin rpy="0 0 0" xyz="0.08 0.0 0.0"/>
      <geometry>
        <box size="0.078 0.110 0.055"/>
      </geometry>
    </collision>
    <collision>
      <origin rpy="0 -1.5707963268 0" xyz="0.019 0 0"/>
      <geometry>
        <cylinder length="0.044" radius="0.05"/>
      </geometry>
    </collision>
  </link>
  <link name="gripper_finger_left">
    <inertial>
      <origin rpy="0 0 0" xyz="0.021935 0.017436 0.0038599"/>
      <mass value="0.1"/>
      <inertia ixx="1.4677E-05" ixy="-7.1238E-06" ixz="3.6153E-06" iyy="1.82E-05" iyz="2.343E-06" izz="2.4607E-05"/>
    </inertial>
    <visual>
      <origin rpy="-1.5707963268 0 0" xyz="0 0 0"/>
      <geometry>
        <mesh filename="package://scorbot_description/meshes/gripper_finger.dae"/>
      </geometry>
      <material name="">
        <color rgba="0.9 0.9 0.9 1"/>
      </material>
    </visual>
    <collision>
      <origin rpy="-1.5707963268 0 0" xyz="0 0 0"/>
      <geometry>
        <mesh filename="package://scorbot_description/meshes/gripper_finger.dae"/>
      </geometry>
    </collision>
  </link>
  <joint name="gripper_finger_left_joint" type="prismatic">
    <origin rpy="0 0 0" xyz="0.118 0.0026 0.010"/>
    <parent link="gripper_base_link"/>
    <child link="gripper_finger_left"/>
    <axis xyz="0 1 0"/>
    <limit effort="30" lower="-0.018" upper="0.016" velocity="1.0"/>
  </joint>
  <link name="gripper_finger_right">
    <inertial>
      <origin rpy="0 0 0" xyz="0.021935 0.014436 -0.0061401"/>
      <mass value="0.1"/>
      <inertia ixx="1.4677E-05" ixy="-7.1238E-06" ixz="3.6153E-06" iyy="1.82E-05" iyz="2.343E-06" izz="2.4607E-05"/>
    </inertial>
    <visual>
      <origin rpy="1.5707963268 0 0" xyz="0 0 0"/>
      <geometry>
        <mesh filename="package://scorbot_description/meshes/gripper_finger.dae"/>
      </geometry>
      <material name="">
        <color rgba="0.9 0.9 0.9 1"/>
      </material>
    </visual>
    <collision>
      <origin rpy="1.5707963268 0 0" xyz="0 0 0"/>
      <geometry>
        <mesh filename="package://scorbot_description/meshes/gripper_finger.dae"/>
      </geometry>
    </collision>
  </link>
  <joint name="gripper_finger_right_joint" type="prismatic">
    <origin rpy="0 0 0" xyz="0.118 -0.0026 -0.010"/>
    <parent link="gripper_base_link"/>
    <child link="gripper_finger_right"/>
    <axis xyz="0 -1 0"/>
    <limit effort="30" lower="-0.018" upper="0.016" velocity="1.0"/>
  </joint>
</robot>

