<?xml version="1.0"?>
<robot
  xmlns:xacro="http://ros.org/wiki/xacro"
  name="scorbot">

  <!-- URDF Materials -->
  <xacro:include filename="$(find scorbot_description)/urdf/materials.urdf.xacro" />
  <!-- Gazebo macros -->
  <xacro:include filename="$(find scorbot_description)/urdf/gazebo.urdf.xacro" />

  <!-- Gazebo elements -->
  <!-- Gazebo Links material -->
  <xacro:gazebo_dae_link link="base" />
  <xacro:gazebo_dae_link link="body" />
  <xacro:gazebo_dae_link link="upper_arm" />
  <xacro:gazebo_dae_link link="forearm" />
  <xacro:gazebo_dae_link link="flange" />
  <xacro:gazebo_dae_link link="right_finger" />
  <xacro:gazebo_dae_link link="left_finger" />

  <!-- Transmissions -->
  <xacro:enable_ros_control prefix="scorbot/"/>
  <xacro:joint_pos_transmission joint="base"/>
  <xacro:joint_pos_transmission joint="shoulder"/>
  <xacro:joint_pos_transmission joint="elbow"/>
  <xacro:joint_pos_transmission joint="pitch"/>
  <xacro:joint_pos_transmission joint="roll"/>
  <xacro:joint_transmission joint="gripper_finger_left_joint"/>
  <xacro:joint_transmission joint="gripper_finger_right_joint"/>

  <!-- Constants -->
  <xacro:property name="M_PI" value="3.14159265359" />
  <xacro:property name="DEG2RAD" value="${M_PI/180.0}" />

  <!-- Joint limits in radians -->
  <xacro:property name="base_upper_limit" value="${ 250.0/2*DEG2RAD}" />
  <xacro:property name="base_lower_limit" value="${-250.0/2*DEG2RAD}" />

  <xacro:property name="shoulder_upper_limit" value="${ 170.0/2*DEG2RAD}" />
  <xacro:property name="shoulder_lower_limit" value="${-170.0/2*DEG2RAD}" />

  <xacro:property name="elbow_upper_limit" value="${ 225.0/2*DEG2RAD}" />
  <xacro:property name="elbow_lower_limit" value="${-225.0/2*DEG2RAD}" />

  <xacro:property name="pitch_upper_limit" value="${ 180.0/2*DEG2RAD}" />
  <xacro:property name="pitch_lower_limit" value="${-180.0/2*DEG2RAD}" />

  <xacro:property name="roll_upper_limit" value="${ 360.0/2*DEG2RAD}" />
  <xacro:property name="roll_lower_limit" value="${-360.0/2*DEG2RAD}" />
  <!-- Gripper joint limits -->
  <xacro:property name="gripper_upper_limit" value="0.016" />
  <xacro:property name="gripper_lower_limit" value="-0.018" />

  <xacro:if value="$(arg fixed)">
    <link name="world"/>
    <joint name="fixed" type="fixed">
      <parent link="world"/>
      <child link="base"/>
    </joint>
  </xacro:if>

  <link
    name="base">
    <inertial>
      <origin
        xyz="-5.6661E-09 -4.8129E-10 0.049865"
        rpy="0 0 0" />
      <mass
        value="3.5594" />
      <inertia
        ixx="0.025688"
        ixy="-2.4368E-10"
        ixz="1.2537E-10"
        iyy="0.025688"
        iyz="-3.2961E-12"
        izz="0.028476" />
    </inertial>
    <visual>
      <origin
        xyz="0 0 0"
        rpy="${M_PI/2.0} 0 0" />
      <geometry>
        <mesh
          filename="package://scorbot_description/meshes/base.dae" />
      </geometry>
      <material
        name="">
        <color
          rgba="0.5 0.5 0.5 1" />
      </material>
    </visual>
    <collision>
      <origin rpy="0 0 0" xyz="0 0 0.0225"/>
      <geometry>
        <cylinder length="0.045" radius="0.16"/>
      </geometry>
    </collision>
    <collision>
      <origin rpy="0 0 0" xyz="0 0 0.085"/>
      <geometry>
        <cylinder length="0.170" radius="0.05"/>
      </geometry>
    </collision>
  </link>
  <link
    name="body">
    <inertial>
      <origin
        xyz="-0.072272 -0.0016694 0.145"
        rpy="0 0 0" />
      <mass
        value="9.7868" />
      <inertia
        ixx="0.05511"
        ixy="-0.001985"
        ixz="0.0061208"
        iyy="0.12037"
        iyz="-0.00070806"
        izz="0.10965" />
    </inertial>
    <visual>
      <origin
        xyz="0 0 0"
        rpy="${-M_PI/2.0} 0 0" />
      <geometry>
        <mesh
          filename="package://scorbot_description/meshes/body.dae" />
      </geometry>
      <material
        name="">
        <color
          rgba="0.5 0.5 0.5 1" />
      </material>
    </visual>
    <collision>
      <origin rpy="0 0 0" xyz="-0.08 0 0.125"/>
      <geometry>
        <box size="0.380 0.18 0.25"/>
      </geometry>
    </collision>
  </link>
  <joint
    name="base"
    type="revolute">
    <origin
      xyz="0 0 0.17"
      rpy="0 0 0" />
    <parent
      link="base" />
    <child
      link="body" />
    <axis
      xyz="0 0 1" />
    <limit effort="30" velocity="1.0" lower="${base_lower_limit}" upper="${base_upper_limit}" />
  </joint>
  <link
    name="upper_arm">
    <inertial>
      <origin
        xyz="0.040893 -0.046847 -6.337E-05"
        rpy="0 0 0" />
      <mass
        value="5.4535" />
      <inertia
        ixx="0.010363"
        ixy="-0.0023486"
        ixz="3.9183E-05"
        iyy="0.1835"
        iyz="-4.8475E-07"
        izz="0.18016" />
    </inertial>
    <visual>
      <origin
        xyz="0 0 0"
        rpy="${-M_PI/2.0} 0 0" />
      <geometry>
        <mesh
          filename="package://scorbot_description/meshes/upper_arm.dae" />
      </geometry>
      <material
        name="">
        <color
          rgba="0.5 0.5 0.5 1" />
      </material>
    </visual>
    <collision>
      <origin rpy="0 0 0" xyz="0.06 -0.06 0"/>
      <geometry>
        <box size="0.60 0.12 0.16"/>
      </geometry>
    </collision>
  </link>
  <joint
    name="shoulder"
    type="revolute">
    <origin
      xyz="0.05 -0.096 0.1885"
      rpy="0 0 0" />
    <parent
      link="body" />
    <child
      link="upper_arm" />
    <axis
      xyz="0 1 0" />
    <limit effort="30" velocity="1.0" lower="${shoulder_lower_limit}" upper="${shoulder_upper_limit}" />
  </joint>
  <link
    name="forearm">
    <inertial>
      <origin
        xyz="0.073997 0.038242 4.5577E-11"
        rpy="0 0 0" />
      <mass
        value="2.194" />
      <inertia
        ixx="0.0025816"
        ixy="5.645E-05"
        ixz="1.195E-11"
        iyy="0.024687"
        iyz="4.1344E-12"
        izz="0.02443" />
    </inertial>
    <visual>
      <origin
        xyz="0 0 0"
        rpy="${M_PI/2.0} 0 0" />
      <geometry>
        <mesh
          filename="package://scorbot_description/meshes/forearm.dae" />
      </geometry>
      <material
        name="">
        <color
          rgba="0.5 0.5 0.5 1" />
      </material>
    </visual>
    <collision>
      <origin rpy="0 0 0" xyz="0.05 0.035 0"/>
      <geometry>
        <box size="0.3 0.095 0.12"/>
      </geometry>
    </collision>
  </link>
  <joint
    name="elbow"
    type="revolute">
    <origin
      xyz="0.3 0.021 0"
      rpy="0 0 0" />
    <parent
      link="upper_arm" />
    <child
      link="forearm" />
    <axis
      xyz="0 -1 0" />
    <limit effort="30" velocity="1.0" lower="${elbow_lower_limit}" upper="${elbow_upper_limit}" />
  </joint>
  <link
    name="flange">
    <inertial>
      <origin
        xyz="0.0069957 -0.02 5.5511E-17"
        rpy="0 0 0" />
      <mass
        value="0.24441" />
      <inertia
        ixx="0.00014819"
        ixy="1.6491E-20"
        ixz="-1.653E-19"
        iyy="0.00028003"
        iyz="5.3591E-21"
        izz="0.00021086" />
    </inertial>
    <visual>
      <origin
        xyz="0 0 0"
        rpy="${-M_PI/2.0} 0 0" />
      <geometry>
        <mesh
          filename="package://scorbot_description/meshes/flange.dae" />
      </geometry>
      <material
        name="">
        <color
          rgba="0.1 0.1 0.1 1" />
      </material>
    </visual>
    <collision>
      <origin rpy="${-M_PI/2.0} 0 0" xyz="0 -0.024 0"/>
      <geometry>
        <cylinder length="0.105" radius="0.05"/>
      </geometry>
    </collision>
  </link>
  <joint
    name="pitch"
    type="revolute">
    <origin
      xyz="0.25 0.058 0"
      rpy="0 0 0" />
    <parent
      link="forearm" />
    <child
      link="flange" />
    <axis
      xyz="0 -1 0" />
    <limit effort="30" velocity="1.0" lower="${pitch_lower_limit}" upper="${pitch_upper_limit}" />
  </joint>

  <joint
    name="roll"
    type="revolute">
    <origin
      xyz="0.054 -0.024 0"
      rpy="0 0 0" />
    <parent
      link="flange" />
    <child
      link="gripper_base_link" />
    <axis
      xyz="-1 0 0" />
    <limit effort="30" velocity="1.0" lower="${roll_lower_limit}" upper="${roll_upper_limit}" />
  </joint>
  <!-- Gripper -->
  <link
    name="gripper_base_link">
    <inertial>
      <origin
        xyz="0.0593648790750631 0 0"
        rpy="0 0 0" />
      <mass
        value="1.59125921054032" />
      <inertia
        ixx="0.00147991252859225"
        ixy="1.34230402513126E-19"
        ixz="1.07467005492524E-19"
        iyy="0.00232303179944379"
        iyz="-4.07594317291221E-20"
        izz="0.00291367454744379" />
    </inertial>
	<visual>
      <origin
        xyz="0 0 0"
        rpy="${-M_PI/2.0} 0 0" />
      <geometry>
        <mesh
          filename="package://scorbot_description/meshes/gripper_base.dae" />
      </geometry>
      <material
        name="">
        <color
          rgba="0.1 0.1 0.1 1" />
      </material>
    </visual>
    <collision>
      <origin rpy="0 0 0" xyz="0.08 0.0 0.0"/>
      <geometry>
        <box size="0.078 0.110 0.055"/>
      </geometry>
    </collision>
    <collision>
      <origin rpy="0 ${-M_PI/2.0} 0" xyz="0.019 0 0"/>
      <geometry>
        <cylinder length="0.044" radius="0.05"/>
      </geometry>
    </collision>
  </link>
  <link
    name="gripper_finger_left">
    <inertial>
      <origin
        xyz="0.021935 0.017436 0.0038599"
        rpy="0 0 0" />
      <mass
        value="0.1" />
      <inertia
        ixx="1.4677E-05"
        ixy="-7.1238E-06"
        ixz="3.6153E-06"
        iyy="1.82E-05"
        iyz="2.343E-06"
        izz="2.4607E-05" />
    </inertial>
    <visual>
      <origin
        xyz="0 0 0"
        rpy="${-M_PI/2.0} 0 0" />
      <geometry>
        <mesh
          filename="package://scorbot_description/meshes/gripper_finger.dae" />
      </geometry>
      <material
        name="">
        <color
          rgba="0.9 0.9 0.9 1" />
      </material>
    </visual>
    <collision>
      <origin
        xyz="0 0 0"
        rpy="${-M_PI/2.0} 0 0" />
      <geometry>
        <mesh
          filename="package://scorbot_description/meshes/gripper_finger.dae" />
      </geometry>
    </collision>
  </link>
  <joint
    name="gripper_finger_left_joint"
    type="prismatic">
    <origin
      xyz="0.118 0.0026 0.010"
      rpy="0 0 0" />
    <parent
      link="gripper_base_link" />
    <child
      link="gripper_finger_left" />
    <axis
      xyz="0 1 0" />
    <limit effort="30" velocity="1.0" lower="${gripper_lower_limit}" upper="${gripper_upper_limit}" />
  </joint>
  <link
    name="gripper_finger_right">
    <inertial>
      <origin
        xyz="0.021935 0.014436 -0.0061401"
        rpy="0 0 0" />
      <mass
        value="0.1" />
      <inertia
        ixx="1.4677E-05"
        ixy="-7.1238E-06"
        ixz="3.6153E-06"
        iyy="1.82E-05"
        iyz="2.343E-06"
        izz="2.4607E-05" />
    </inertial>
    <visual>
      <origin
        xyz="0 0 0"
        rpy="${M_PI/2.0} 0 0" />
      <geometry>
        <mesh
          filename="package://scorbot_description/meshes/gripper_finger.dae" />
      </geometry>
      <material
        name="">
        <color
          rgba="0.9 0.9 0.9 1" />
      </material>
    </visual>
    <collision>
      <origin
        xyz="0 0 0"
        rpy="${M_PI/2.0} 0 0" />
      <geometry>
        <mesh
          filename="package://scorbot_description/meshes/gripper_finger.dae" />
      </geometry>
    </collision>
  </link>
  <joint
    name="gripper_finger_right_joint"
    type="prismatic">
    <origin
      xyz="0.118 -0.0026 -0.010"
      rpy="0 0 0" />
    <parent
      link="gripper_base_link" />
    <child
      link="gripper_finger_right" />
    <axis
      xyz="0 -1 0" />
    <limit effort="30" velocity="1.0" lower="${gripper_lower_limit}" upper="${gripper_upper_limit}" />
  </joint>
</robot>
